<?xml version="1.0" encoding="utf-8"?>
<!-- This URDF was automatically created by SolidWorks to URDF Exporter! Originally created by Stephen Brawner (brawner@gmail.com) 
     Commit Version: 1.6.0-1-g15f4949  Build Version: 1.6.7594.29634
     For more information, please see http://wiki.ros.org/sw_urdf_exporter -->
<robot
  name="my_robot">
  <link
    name="base_link">
    <inertial>
      <origin
        xyz="0.0587853718852618 -0.0930559935631688 1.03726776096917E-15"
        rpy="0 0 0" />
      <mass
        value="3.12236517080468" />
      <inertia
        ixx="0.121295108305808"
        ixy="0.0195662603783679"
        ixz="1.24119464706141E-15"
        iyy="0.374823982635833"
        iyz="-4.44414470501808E-16"
        izz="0.303669234388361" />
    </inertial>
    <visual>
      <origin
        xyz="0 0 0"
        rpy="0 0 0" />
      <geometry>
        <mesh
          filename="package://my_robot/meshes/base_link.STL" />
      </geometry>
      <material
        name="">
        <color
          rgba="0.6 0.6 0.6 1" />
      </material>
    </visual>
    <collision>
      <origin
        xyz="0 0 0"
        rpy="0 0 0" />
      <geometry>
        <mesh
          filename="package://my_robot/meshes/base_link.STL" />
      </geometry>
    </collision>
  </link>
  <link
    name="left_front_wheel">
    <inertial>
      <origin
        xyz="5.13930929757489E-09 -3.04509164550382E-08 -0.0552248163410726"
        rpy="0 0 0" />
      <mass
        value="8.23195517435844" />
      <inertia
        ixx="0.0630064366723534"
        ixy="-1.07299508427666E-08"
        ixz="-2.54046412544519E-09"
        iyy="0.0630064355833204"
        iyz="-1.2711075666515E-08"
        izz="0.108767039452199" />
    </inertial>
    <visual>
      <origin
        xyz="0 0 0"
        rpy="0 0 0" />
      <geometry>
        <mesh
          filename="package://my_robot/meshes/left_front_wheel.STL" />
      </geometry>
      <material
        name="">
        <color
          rgba="0.298039215686275 0.298039215686275 0.298039215686275 1" />
      </material>
    </visual>
    <collision>
      <origin
        xyz="0 0 0"
        rpy="0 0 0" />
      <geometry>
        <mesh
          filename="package://my_robot/meshes/left_front_wheel.STL" />
      </geometry>
    </collision>
  </link>
  <joint
    name="left_front_wheel_joint"
    type="continuous">
    <origin
      xyz="0.256 0.22035 -0.1953"
      rpy="-1.5708 1.2311 -3.1416" />
    <parent
      link="base_link" />
    <child
      link="left_front_wheel" />
    <axis
      xyz="0 0 1" />
  </joint>
  <link
    name="left_rear_wheel">
    <inertial>
      <origin
        xyz="5.13930895063019E-09 -3.04509163440159E-08 -0.0552248163410726"
        rpy="0 0 0" />
      <mass
        value="8.23195517435845" />
      <inertia
        ixx="0.0630064366723535"
        ixy="-1.07299508392972E-08"
        ixz="-2.54046391580306E-09"
        iyy="0.0630064355833206"
        iyz="-1.27110757684258E-08"
        izz="0.108767039452199" />
    </inertial>
    <visual>
      <origin
        xyz="0 0 0"
        rpy="0 0 0" />
      <geometry>
        <mesh
          filename="package://my_robot/meshes/left_rear_wheel.STL" />
      </geometry>
      <material
        name="">
        <color
          rgba="0.298039215686275 0.298039215686275 0.298039215686275 1" />
      </material>
    </visual>
    <collision>
      <origin
        xyz="0 0 0"
        rpy="0 0 0" />
      <geometry>
        <mesh
          filename="package://my_robot/meshes/left_rear_wheel.STL" />
      </geometry>
    </collision>
  </link>
  <joint
    name="left_rear_wheel_joint"
    type="continuous">
    <origin
      xyz="-0.256 0.22035 -0.1953"
      rpy="-1.5708 -0.33051 3.1416" />
    <parent
      link="base_link" />
    <child
      link="left_rear_wheel" />
    <axis
      xyz="0 0 1" />
  </joint>
  <link
    name="right_rear_wheel">
    <inertial>
      <origin
        xyz="8.15809958476521E-09 -2.57078605625516E-09 -0.0552248254929292"
        rpy="0 0 0" />
      <mass
        value="8.23195748178054" />
      <inertia
        ixx="0.063006463055454"
        ixy="-1.12729348269308E-08"
        ixz="-1.17763979744703E-09"
        iyy="0.0630064519403229"
        iyz="-4.45415611022009E-09"
        izz="0.108767077064945" />
    </inertial>
    <visual>
      <origin
        xyz="0 0 0"
        rpy="0 0 0" />
      <geometry>
        <mesh
          filename="package://my_robot/meshes/right_rear_wheel.STL" />
      </geometry>
      <material
        name="">
        <color
          rgba="0.298039215686275 0.298039215686275 0.298039215686275 1" />
      </material>
    </visual>
    <collision>
      <origin
        xyz="0 0 0"
        rpy="0 0 0" />
      <geometry>
        <mesh
          filename="package://my_robot/meshes/right_rear_wheel.STL" />
      </geometry>
    </collision>
  </link>
  <joint
    name="right_rear_wheel_joint"
    type="continuous">
    <origin
      xyz="-0.256 -0.22035 -0.1953"
      rpy="1.5708 1.2718 -3.1416" />
    <parent
      link="base_link" />
    <child
      link="right_rear_wheel" />
    <axis
      xyz="0 0 1" />
  </joint>
  <link
    name="right_front_wheel">
    <inertial>
      <origin
        xyz="-5.98366356463487E-11 -2.31314772891622E-08 0.0590751828145294"
        rpy="0 0 0" />
      <mass
        value="8.2319551743634" />
      <inertia
        ixx="0.0630064451523927"
        ixy="-1.43715566647794E-08"
        ixz="-3.04950039790996E-09"
        iyy="0.0630064261207298"
        iyz="-1.0117224101023E-08"
        izz="0.10876703761934" />
    </inertial>
    <visual>
      <origin
        xyz="0 0 0"
        rpy="0 0 0" />
      <geometry>
        <mesh
          filename="package://my_robot/meshes/right_front_wheel.STL" />
      </geometry>
      <material
        name="">
        <color
          rgba="0.298039215686275 0.298039215686275 0.298039215686275 1" />
      </material>
    </visual>
    <collision>
      <origin
        xyz="0 0 0"
        rpy="0 0 0" />
      <geometry>
        <mesh
          filename="package://my_robot/meshes/right_front_wheel.STL" />
      </geometry>
    </collision>
  </link>
  <joint
    name="right_front_wheel_joint"
    type="continuous">
    <origin
      xyz="0.256 -0.33465 -0.1953"
      rpy="1.5708 -1.4489 3.1416" />
    <parent
      link="base_link" />
    <child
      link="right_front_wheel" />
    <axis
      xyz="0 0 1" />
  </joint>
</robot>