<?xml version="1.0" encoding="utf-8"?>
<!-- This URDF was automatically created by SolidWorks to URDF Exporter! Originally created by Stephen Brawner (brawner@gmail.com) 
     Commit Version: 1.6.0-1-g15f4949  Build Version: 1.6.7594.29634
     For more information, please see http://wiki.ros.org/sw_urdf_exporter -->
<robot
  name="my_robot">
  <link
    name="base_link">
    <inertial>
      <origin
        xyz="-3.13347090083884E-16 -0.0930559935631705 0.058785371885261"
        rpy="0 0 0" />
      <mass
        value="3.12236517080469" />
      <inertia
        ixx="0.303669234388361"
        ixy="-1.47668335892526E-16"
        ixz="-2.24646690138997E-16"
        iyy="0.374823982635836"
        iyz="0.0195662603783682"
        izz="0.121295108305807" />
    </inertial>
    <visual>
      <origin
        xyz="0 0 0"
        rpy="0 0 0" />
      <geometry>
        <mesh
          filename="package://my_robot/meshes/base_link.STL" />
      </geometry>
      <material
        name="">
        <color
          rgba="0.6 0.6 0.6 1" />
      </material>
    </visual>
    <collision>
      <origin
        xyz="0 0 0"
        rpy="0 0 0" />
      <geometry>
        <mesh
          filename="package://my_robot/meshes/base_link.STL" />
      </geometry>
    </collision>
  </link>
  <link
    name="right_front_wheel">
    <inertial>
      <origin
        xyz="8.1581E-09 -2.5707E-09 -0.055225"
        rpy="0 0 0" />
      <mass
        value="8.232" />
      <inertia
        ixx="0.063006"
        ixy="-1.1273E-08"
        ixz="-1.1776E-09"
        iyy="0.063006"
        iyz="-4.4541E-09"
        izz="0.10877" />
    </inertial>
    <visual>
      <origin
        xyz="0 0 0"
        rpy="0 0 0" />
      <geometry>
        <mesh
          filename="package://my_robot/meshes/right_front_wheel.STL" />
      </geometry>
      <material
        name="">
        <color
          rgba="0.29804 0.29804 0.29804 1" />
      </material>
    </visual>
    <collision>
      <origin
        xyz="0 0 0"
        rpy="0 0 0" />
      <geometry>
        <mesh
          filename="package://my_robot/meshes/right_front_wheel.STL" />
      </geometry>
    </collision>
  </link>
  <joint
    name="right_front_wheel_joint"
    type="continuous">
    <origin
      xyz="-0.2775 -0.256 -0.1953"
      rpy="1.5708 1.2996 1.5708" />
    <parent
      link="base_link" />
    <child
      link="right_front_wheel" />
    <axis
      xyz="0 0 1" />
  </joint>
  <link
    name="right_rear_wheel">
    <inertial>
      <origin
        xyz="8.1547E-09 -2.5707E-09 -0.055225"
        rpy="0 0 0" />
      <mass
        value="8.232" />
      <inertia
        ixx="0.063006"
        ixy="-1.1273E-08"
        ixz="-1.1783E-09"
        iyy="0.063006"
        iyz="-4.4541E-09"
        izz="0.10877" />
    </inertial>
    <visual>
      <origin
        xyz="0 0 0"
        rpy="0 0 0" />
      <geometry>
        <mesh
          filename="package://my_robot/meshes/right_rear_wheel.STL" />
      </geometry>
      <material
        name="">
        <color
          rgba="0.29804 0.29804 0.29804 1" />
      </material>
    </visual>
    <collision>
      <origin
        xyz="0 0 0"
        rpy="0 0 0" />
      <geometry>
        <mesh
          filename="package://my_robot/meshes/right_rear_wheel.STL" />
      </geometry>
    </collision>
  </link>
  <joint
    name="right_rear_wheel_joint"
    type="continuous">
    <origin
      xyz="-0.2775 0.256 -0.1953"
      rpy="-1.5708 -0.87872 -1.5708" />
    <parent
      link="base_link" />
    <child
      link="right_rear_wheel" />
    <axis
      xyz="0 0 1" />
  </joint>
  <link
    name="left_rear_wheel">
    <inertial>
      <origin
        xyz="-4.0169E-09 -1.5027E-08 -0.055225"
        rpy="0 0 0" />
      <mass
        value="8.232" />
      <inertia
        ixx="0.063006"
        ixy="-2.0152E-09"
        ixz="-5.1018E-09"
        iyy="0.063006"
        iyz="-8.3454E-09"
        izz="0.10877" />
    </inertial>
    <visual>
      <origin
        xyz="0 0 0"
        rpy="0 0 0" />
      <geometry>
        <mesh
          filename="package://my_robot/meshes/left_rear_wheel.STL" />
      </geometry>
      <material
        name="">
        <color
          rgba="0.29804 0.29804 0.29804 1" />
      </material>
    </visual>
    <collision>
      <origin
        xyz="0 0 0"
        rpy="0 0 0" />
      <geometry>
        <mesh
          filename="package://my_robot/meshes/left_rear_wheel.STL" />
      </geometry>
    </collision>
  </link>
  <joint
    name="left_rear_wheel_joint"
    type="continuous">
    <origin
      xyz="0.2775 0.256 -0.1953"
      rpy="1.5708 0.72361 -1.5708" />
    <parent
      link="base_link" />
    <child
      link="left_rear_wheel" />
    <axis
      xyz="0 0 1" />
  </joint>
  <link
    name="left_front_wheel">
    <inertial>
      <origin
        xyz="-4.0169E-09 -1.5027E-08 -0.055225"
        rpy="0 0 0" />
      <mass
        value="8.232" />
      <inertia
        ixx="0.063006"
        ixy="-2.0152E-09"
        ixz="-5.1018E-09"
        iyy="0.063006"
        iyz="-8.3454E-09"
        izz="0.10877" />
    </inertial>
    <visual>
      <origin
        xyz="0 0 0"
        rpy="0 0 0" />
      <geometry>
        <mesh
          filename="package://my_robot/meshes/left_front_wheel.STL" />
      </geometry>
      <material
        name="">
        <color
          rgba="0.29804 0.29804 0.29804 1" />
      </material>
    </visual>
    <collision>
      <origin
        xyz="0 0 0"
        rpy="0 0 0" />
      <geometry>
        <mesh
          filename="package://my_robot/meshes/left_front_wheel.STL" />
      </geometry>
    </collision>
  </link>
  <joint
    name="left_front_wheel_joint"
    type="continuous">
    <origin
      xyz="0.2775 -0.256 -0.1953"
      rpy="1.5708 -0.83796 -1.5708" />
    <parent
      link="base_link" />
    <child
      link="left_front_wheel" />
    <axis
      xyz="0 0 1" />
  </joint>
</robot>