<?xml version="1.0" encoding="utf-8"?>
<!-- This URDF was automatically created by SolidWorks to URDF Exporter! Originally created by Stephen Brawner (brawner@gmail.com) 
     Commit Version: 1.6.0-1-g15f4949  Build Version: 1.6.7594.29634
     For more information, please see http://wiki.ros.org/sw_urdf_exporter -->
<robot
  name="my_robot_collision">
  <link
    name="base_link">
    <inertial>
      <origin
        xyz="0.057384 0.00028598 -0.089396"
        rpy="0 0 0" />
      <mass
        value="3.1224" />
      <inertia
        ixx="0.1213"
        ixy="-1.2929E-15"
        ixz="0.019566"
        iyy="0.30367"
        iyz="4.1462E-16"
        izz="0.37482" />
    </inertial>
    <visual>
      <origin
        xyz="0 0 0"
        rpy="0 0 0" />
      <geometry>
        <mesh
          filename="package://my_robot_collision/meshes/base_link.STL" />
      </geometry>
      <material
        name="">
        <color
          rgba="0.6 0.6 0.6 1" />
      </material>
    </visual>
    <collision>
      <origin
        xyz="0 0 0"
        rpy="0 0 0" />
      <geometry>
        <mesh
          filename="package://my_robot_collision/meshes/base_link.STL" />
      </geometry>
    </collision>
  </link>
  <link
    name="left_front_wheel">
    <inertial>
      <origin
        xyz="-0.0029842 -0.0025408 -0.055741"
        rpy="0 0 0" />
      <mass
        value="9.1523" />
      <inertia
        ixx="0.076"
        ixy="3.4694E-18"
        ixz="-1.8614E-16"
        iyy="0.076"
        iyz="-6.6273E-17"
        izz="0.13212" />
    </inertial>
    <visual>
      <origin
        xyz="0 0 0"
        rpy="0 0 0" />
      <geometry>
        <mesh
          filename="package://my_robot_collision/meshes/left_front_wheel.STL" />
      </geometry>
      <material
        name="">
        <color
          rgba="0.29804 0.29804 0.29804 1" />
      </material>
    </visual>
    <collision>
      <origin
        xyz="0 0 0"
        rpy="0 0 0" />
      <geometry>
        <mesh
          filename="package://my_robot_collision/meshes/left_front_wheel.STL" />
      </geometry>
    </collision>
  </link>
  <joint
    name="left_front_wheel_joint"
    type="continuous">
    <origin
      xyz="0.256 0.22035 -0.1953"
      rpy="-1.5708 1.2311 -3.1416" />
    <parent
      link="base_link" />
    <child
      link="left_front_wheel" />
    <axis
      xyz="0 0 1" />
  </joint>
  <link
    name="left_rear_wheel">
    <inertial>
      <origin
        xyz="0.0025131 -0.0030076 -0.055741"
        rpy="0 0 0" />
      <mass
        value="9.1523" />
      <inertia
        ixx="0.076"
        ixy="-3.4694E-18"
        ixz="6.2837E-17"
        iyy="0.076"
        iyz="-1.8591E-16"
        izz="0.13212" />
    </inertial>
    <visual>
      <origin
        xyz="0 0 0"
        rpy="0 0 0" />
      <geometry>
        <mesh
          filename="package://my_robot_collision/meshes/left_rear_wheel.STL" />
      </geometry>
      <material
        name="">
        <color
          rgba="0.29804 0.29804 0.29804 1" />
      </material>
    </visual>
    <collision>
      <origin
        xyz="0 0 0"
        rpy="0 0 0" />
      <geometry>
        <mesh
          filename="package://my_robot_collision/meshes/left_rear_wheel.STL" />
      </geometry>
    </collision>
  </link>
  <joint
    name="left_rear_wheel_joint"
    type="continuous">
    <origin
      xyz="-0.256 0.22035 -0.1953"
      rpy="-1.5708 -0.33051 3.1416" />
    <parent
      link="base_link" />
    <child
      link="left_rear_wheel" />
    <axis
      xyz="0 0 1" />
  </joint>
  <link
    name="right_rear_wheel">
    <inertial>
      <origin
        xyz="-0.0030853 0.0024171 -0.055169"
        rpy="0 0 0" />
      <mass
        value="9.1523" />
      <inertia
        ixx="0.076"
        ixy="0"
        ixz="-1.8538E-16"
        iyy="0.076"
        iyz="5.6476E-17"
        izz="0.13212" />
    </inertial>
    <visual>
      <origin
        xyz="0 0 0"
        rpy="0 0 0" />
      <geometry>
        <mesh
          filename="package://my_robot_collision/meshes/right_rear_wheel.STL" />
      </geometry>
      <material
        name="">
        <color
          rgba="0.29804 0.29804 0.29804 1" />
      </material>
    </visual>
    <collision>
      <origin
        xyz="0 0 0"
        rpy="0 0 0" />
      <geometry>
        <mesh
          filename="package://my_robot_collision/meshes/right_rear_wheel.STL" />
      </geometry>
    </collision>
  </link>
  <joint
    name="right_rear_wheel_joint"
    type="continuous">
    <origin
      xyz="-0.256 -0.22035 -0.1953"
      rpy="1.5708 1.2718 -3.1416" />
    <parent
      link="base_link" />
    <child
      link="right_rear_wheel" />
    <axis
      xyz="0 0 1" />
  </joint>
  <link
    name="right_front_wheel">
    <inertial>
      <origin
        xyz="2.2204E-16 2.7756E-17 0.058845"
        rpy="0 0 0" />
      <mass
        value="9.1523" />
      <inertia
        ixx="0.076"
        ixy="0"
        ixz="1.9302E-16"
        iyy="0.076"
        iyz="2.3818E-17"
        izz="0.13212" />
    </inertial>
    <visual>
      <origin
        xyz="0 0 0"
        rpy="0 0 0" />
      <geometry>
        <mesh
          filename="package://my_robot_collision/meshes/right_front_wheel.STL" />
      </geometry>
      <material
        name="">
        <color
          rgba="0.29804 0.29804 0.29804 1" />
      </material>
    </visual>
    <collision>
      <origin
        xyz="0 0 0"
        rpy="0 0 0" />
      <geometry>
        <mesh
          filename="package://my_robot_collision/meshes/right_front_wheel.STL" />
      </geometry>
    </collision>
  </link>
  <joint
    name="right_front_wheel_joint"
    type="continuous">
    <origin
      xyz="0.256 -0.33465 -0.1953"
      rpy="1.5708 -1.4489 3.1416" />
    <parent
      link="base_link" />
    <child
      link="right_front_wheel" />
    <axis
      xyz="0 0 1" />
  </joint>
</robot>